test_data/snapshot_asks.csv
price,size,side
8014,0.00646934,sell
8014.34,0.001,sell
8015,0.021821,sell
8015.15,0.006,sell
8015.19,0.02384074,sell
8015.35,0.1,sell
8015.37,0.5,sell
8016,0.001,sell
8016.06,0.0048,sell
8017,2.22417657,sell
8017.88,0.0024,sell
8018,0.001,sell
8018.54,0.6952,sell
8018.55,0.906,sell
8019,0.001,sell
8019.02,0.00468,sell
8019.05,5.09,sell
8019.36,0.0755,sell
8019.52,0.2,sell
8020,8.38835845,sell
8020.01,1.65284524,sell
8020.03,0.00161652,sell
8020.2,0.1,sell
8020.23,0.18,sell
8020.99,0.00270521,sell
8021,0.001,sell
8021.1,0.14103666,sell
8021.21,0.20796156,sell
8021.64,1.01294127,sell
8021.99,1.0129716,sell
8022,70.001,sell
8022.01,0.55393249,sell
8022.08,0.001,sell
8022.93,2,sell
8022.98,0.12791,sell
8023,0.3657,sell
8023.24,5.3,sell
8023.53,0.09313837,sell
8023.89,0.00563817,sell
8024,0.001,sell
8024.13,0.001,sell
8024.15,0.001,sell
8024.28,0.001,sell
8024.3,0.001,sell
8024.44,0.001,sell
8024.61,0.00270386,sell
8024.65,0.01,sell
8024.97,9.6415,sell
8024.99,0.015,sell
8025,11.31484715,sell
8025.43,0.00704526,sell
8025.65,0.001,sell
8025.7,0.0104105,sell
8025.83,0.002,sell
8025.99,0.001,sell
8026,0.001,sell
8026.21,0.035,sell
8026.22,0.0024,sell
8026.49,0.00217981,sell
8026.81,0.001,sell
8026.94,0.001,sell
8027,0.001,sell
8027.06,0.001,sell
8027.18,1,sell
8027.19,5.42,sell
8027.32,0.002505,sell
8027.49,0.001,sell
8027.73,2,sell
8028,0.101,sell
8028.22,2.769,sell
8028.37,0.02,sell
8028.86,0.01270251,sell
8029,0.02637186,sell
8029.29,0.001,sell
8029.83,0.002,sell
8030,0.79996705,sell
8030.12,1,sell
8030.5,0.001,sell
8030.51,0.0312,sell
8030.76,0.001,sell
8030.78,0.015633,sell
8031,0.001,sell
8031.04,0.01478915,sell
8031.98,4.6,sell
8032,0.49900797,sell
8032.71,0.0048,sell
8032.99,0.01,sell
8033,4.001,sell
8033.17,0.0096,sell
8033.83,0.002,sell
8033.88,0.01370092,sell
8034,0.001,sell
8034.56,0.0024,sell
8034.99,0.016,sell
8035,0.31084654,sell
8035.12,0.001,sell
8035.99,0.5687,sell
8036,1.001,sell
8036.18,5.8,sell
8036.43,1.25194999,sell
8036.54,0.00217708,sell
8036.87,0.05143614,sell
8037,0.501,sell
8037.18,13,sell
8037.37,2.00516686,sell
8037.54,0.00178,sell
8038,0.002,sell
8038.04,0.015619,sell
8038.56,0.03,sell
8038.99,0.01,sell
8039,0.001,sell
8039.08,0.001,sell
8039.12,0.02,sell
8039.22,0.0054446,sell
8039.87,4.1,sell
8039.99,0.001,sell
8040,4.0683938,sell
8040.07,0.00768362,sell
8040.09,0.09,sell
8040.58,0.001,sell
8040.69,0.011967,sell
8040.99,0.002,sell
8041,0.001,sell
8041.23,0.001,sell
8041.54,0.002,sell
8041.73,0.001246,sell
8041.75,5,sell
8042,0.101,sell
8042.67,0.883,sell
8042.9,0.0024,sell
8043,0.001,sell
8043.95,0.00563511,sell
8044,0.03683583,sell
8044.21,4.33,sell
8044.92,1.581,sell
8044.99,0.016,sell
8045,0.86231235,sell
8045.04,19.458,sell
8045.29,0.015605,sell
8045.5,0.001,sell
8045.7,0.02,sell
8045.86,0.00739585,sell
8045.99,0.003,sell
8046,0.002,sell
8046.03,0.1298,sell
8046.14,0.01,sell
8046.39,0.00162,sell
8046.53,0.09,sell
8046.6,0.00218921,sell
8047,0.001,sell
8047.16,0.001,sell
8047.3,0.0301,sell
8047.66,4.3,sell
8048,0.81101776,sell
8048.05,6.5,sell
8049,0.4437,sell
8049.37,0.0048,sell
8049.63,0.001,sell
8049.91,0.0037,sell
8050,28.76455697,sell
8050.2,0.001,sell
8050.65,0.001,sell
8051,3.16088,sell
8051.03,0.01,sell
8051.24,0.0024,sell
8051.99,0.001,sell
8052,0.001,sell
8052.14,0.01,sell
8052.32,0.01,sell
8052.55,0.01559,sell
8052.68,0.002,sell
8052.76,0.001,sell
8053,0.002,sell
8054,0.211,sell
8054.2,0.00491853,sell
8054.64,0.001,sell
8054.65,0.001,sell
8054.99,0.015,sell
8055,0.284,sell
8055.99,0.00315,sell
8056,0.001,sell
8056.67,0.00218903,sell
8056.91,0.00125,sell
8056.99,0.001,sell
8057,0.001,sell
8057.03,5,sell
8057.05,9.337,sell
8057.88,0.1448,sell
8058,0.03218834,sell
8058.14,0.01,sell
8058.2,0.001,sell
8058.65,0.001,sell
8058.69,19.14,sell
8059,0.001,sell
8059.12,0.001,sell
8059.58,0.0024,sell
8060,0.7177695,sell
8060.5,0.001,sell
8061,0.001,sell
8061.02,0.09,sell
8061.98,0.3,sell
8061.99,0.001,sell
8062,0.001,sell
8062.2,0.001,sell
8062.47,0.02,sell
8062.63,0.09,sell
8063,0.001,sell
8063.04,0.63174521,sell
8063.41,0.01,sell
8064,0.001,sell
8064.04,0.01464039,sell
8064.14,0.0128,sell
8064.16,0.00539537,sell
8064.99,0.02,sell
8065,0.002,sell
8065.27,0.001,sell
8065.67,1.499,sell
8065.82,0.75,sell
8065.99,0.001,sell
8066,0.062,sell
8066.03,0.0048,sell
8066.2,0.001,sell
8066.34,0.00775833,sell
8066.51,0.0096,sell
8066.75,0.00219797,sell
8066.99,0.001,sell
8067,0.001,sell
8067.71,5,sell
8067.72,0.2,sell
8067.92,1.2354,sell
8068,0.001,sell
8069,0.00324813,sell
8069.14,0.37194271,sell
8069.27,0.001,sell
8070,0.297,sell
8070.14,0.01,sell
8070.2,0.001,sell
8070.7,0.09,sell
8070.72,0.0311,sell
8070.78,0.14481,sell
8071,0.001,sell
8071.1,0.001,sell
8071.76,0.079,sell
8071.93,0.00162,sell
8071.99,0.001,sell
8072,0.01117,sell
8072.13,0.15,sell
8072.31,0.09,sell
8073,0.001,sell
8073.27,0.001,sell
8073.33,0.1030663,sell
8073.83,0.0013,sell
8073.93,0.09,sell
8074,0.001,sell
8074.2,0.001,sell
8074.54,4.565,sell
8074.99,0.015,sell
8075,5.37414597,sell
8075.37,12.5195,sell
8075.5,0.001,sell
8075.54,0.09,sell
8075.99,0.001,sell
8076,0.002,sell
8076.14,0.01,sell
8076.26,0.0024,sell
8076.85,0.00219687,sell
8076.99,0.001,sell
8077,0.011,sell
8077.16,0.09,sell
8077.25,0.00241415,sell
8077.27,0.001,sell
8078,1.001,sell
8078.18,0.00117596,sell
8078.2,0.001,sell
8078.33,0.0148088,sell
8078.66,0.0019184,sell
8078.67,0.00216605,sell
8078.68,0.00117561,sell
8078.69,0.00117557,sell
8078.7,0.00216584,sell
8078.71,0.00241348,sell
8078.72,0.00117586,sell
8078.73,0.0016708,sell
8078.74,0.00191844,sell
8078.75,0.00228962,sell
8078.76,0.00191828,sell
8078.77,0.09,sell
8079,0.4234543,sell
8079.49,0.33278458,sell
8079.7,17.9,sell
8079.75,0.045,sell
8079.99,0.001,sell
8080,0.72486461,sell
8080.2,0.00173634,sell
8080.39,0.09,sell
8081,0.001,sell
8081.27,0.001,sell
8081.97,0.00154662,sell
8081.98,0.00154658,sell
8081.99,0.001,sell
8082,0.091,sell
8082.14,0.01,sell
8082.2,0.001,sell
8082.69,0.0048,sell
8082.79,1,sell
8082.8,0.001,sell
8082.92,0.00117513,sell
8082.93,0.00117516,sell
8082.94,0.00241241,sell
8082.95,0.00204126,sell
8082.96,0.00117503,sell
8082.97,0.00216477,sell
8082.98,0.00179363,sell
8082.99,0.00241224,sell
8083,0.02290266,sell
8083.32,0.0022883,sell
8083.33,0.03961069,sell
8083.62,0.09,sell
8083.69,0.1448,sell
8084,0.001,sell
8084.02,0.00568078,sell
8084.6,0.0024,sell
8084.71,0.12,sell
8084.81,0.0592,sell
8084.99,0.015,sell
8085,0.951,sell
8085.18,0.001,sell
8085.24,0.09,sell
8085.27,0.001,sell
8085.99,0.01384309,sell
8086,1.97810676,sell
8086.08,0.001,sell
8086.2,0.001,sell
8086.28,0.0017,sell
8086.86,0.09,sell
8086.87,0.00814501,sell
8086.96,0.00219416,sell
8086.99,0.001,sell
8087,0.011,sell
8087.55,0.01,sell
8088,2.11305489,sell
8088.12,0.025,sell
8088.14,0.01,sell
8088.24,0.01,sell
8088.26,0.079,sell
8088.47,0.09,sell
8088.88,10,sell
8089,2.351,sell
8089.12,0.001,sell
8089.27,0.001,sell
8089.76,0.35,sell
8090,0.642,sell
8090.09,0.09,sell
8090.2,0.001,sell
8090.5,0.001,sell
8091,0.001,sell
8091.08,0.001,sell
8091.23,0.001,sell
8091.4,0.00179,sell
8091.45,0.42502127,sell
8091.71,0.09,sell
8091.99,0.001,sell
8092,0.242,sell
8092.01,0.04886843,sell
8092.68,0.032,sell
8092.94,0.00069,sell
8093,0.001,sell
8093.27,0.001,sell
8093.33,0.09,sell
8093.39,0.006,sell
8093.8,0.01,sell
8094,0.001,sell
8094.14,0.01,sell
8094.2,0.001,sell
8094.95,0.09,sell
8094.99,0.015,sell
8095,0.181,sell
8095.02,0.41665,sell
8095.08,0.0016,sell
8095.46,1,sell
8095.62,0.01259391,sell
8095.99,0.001,sell
8096,0.551,sell
8096.08,0.001,sell
8096.56,0.09,sell
8096.91,0.97565252,sell
8096.95,0.10617974,sell
8096.99,0.001,sell
8097,0.011,sell
8097.03,3.265,sell
8097.08,0.001,sell
8097.09,0.00220623,sell
8097.27,0.001,sell
8097.72,20.73,sell
8098,0.53572718,sell
8098.18,0.09,sell
8098.2,0.001,sell
8098.5,0.1,sell
8098.96,3.12909559,sell
8099,0.8913587,sell
8099.35,0.0048,sell
8099.5,0.39551868,sell
8099.8,0.09,sell
8099.84,0.0296,sell
8099.98,0.00112542,sell
8099.99,0.14117152,sell
8100,11.4264281,sell
8100.14,0.01,sell
8100.26,0.00167,sell
8101,1.283,sell
8101.08,0.001,sell
