test_data/snapshot_bids.csv
price,size,side
8337.66,1.92259307,buy
8337,0.001,buy
8336,0.001,buy
8335.83,0.9,buy
8335.65,0.01,buy
8335.5,0.01,buy
8335.48,0.01,buy
8335.39,0.01,buy
8335.31,0.01,buy
8335.3,0.01,buy
8335.13,0.01,buy
8335,0.001,buy
8334.86,0.01,buy
8334.8,0.01,buy
8334.79,0.01,buy
8334.59,0.001,buy
8334.33,0.00181,buy
8334.3,0.01,buy
8334.13,0.001,buy
8334,0.001,buy
8333.8,0.01,buy
8333.3,0.01,buy
8333,0.001,buy
8332.9,0.01,buy
8332.8,0.01,buy
8332.6,0.77566187,buy
8332.35,0.01,buy
8332.3,0.01,buy
8332.2,0.01,buy
8332.11,0.01,buy
8332.1,0.01,buy
8332,0.001,buy
8331,0.001,buy
8330.59,0.31182,buy
8330,2.81908,buy
8329.31,0.46565057,buy
8329.26,0.32592,buy
8329.21,0.001,buy
8329,0.121,buy
8328.91,0.01,buy
8328,0.001,buy
8327.5,0.01,buy
8327.19,0.01,buy
8327,0.937,buy
8326.99,0.03428679,buy
8326.97,0.14366376,buy
8326.96,0.1,buy
8326.5,0.01260121,buy
8326.46,0.0024,buy
8326.24,0.001,buy
8326.15,1,buy
8326.03,0.95533348,buy
8326.01,0.031,buy
8326,0.011,buy
8325.94,0.001,buy
8325.18,0.001,buy
8325.02,1,buy
8325.01,0.5,buy
8325,12.38563962,buy
8324,0.001,buy
8323.92,0.009,buy
8323.55,0.006,buy
8323.03,0.001,buy
8323,0.001,buy
8322.96,0.001,buy
8322.58,0.015,buy
8322.57,0.03,buy
8322.23,0.00260251,buy
8322,0.001,buy
8321.89,0.5,buy
8321.62,0.01,buy
8321.6,0.03,buy
8321.48,0.002,buy
8321.44,0.001,buy
8321.43,0.001,buy
8321.35,0.002,buy
8321.32,0.003,buy
8321.31,0.001,buy
8321.28,3.8,buy
8321.22,0.003,buy
8321.21,0.003,buy
8321.2,0.003,buy
8321.19,0.003,buy
8321.09,0.003,buy
8321.07,0.003,buy
8321,0.001,buy
8320.97,0.899999,buy
8320.62,0.00309633,buy
8320.15,0.012019,buy
8320,6.34528646,buy
8319.53,0.001,buy
8319,0.001,buy
8318.58,0.05,buy
8318.5,0.00856817,buy
8318.23,0.01126681,buy
8318.12,0.07449206,buy
8318.09,7.4751,buy
8318,0.001,buy
8317.6,4.2,buy
8317.22,2,buy
8317.2,0.0085,buy
8317.18,2.236,buy
8317.11,0.001,buy
8317.02,1,buy
8317,0.001,buy
8316.47,1.405,buy
8316.35,0.001,buy
8316.32,0.001,buy
8316,0.151,buy
8315.93,0.0048,buy
8315.87,0.001,buy
8315.66,1.476,buy
8315.42,1.64176573,buy
8315.3,0.04581597,buy
8315,1.001,buy
8314.57,0.001,buy
8314.24,0.00260511,buy
8314,0.001,buy
8313.53,3.88,buy
8313.12,0.2,buy
8313,0.001,buy
8312.5,0.00224147,buy
8312,0.282,buy
8311.79,1.502,buy
8311.19,0.001,buy
8311,0.001,buy
8310.42,2,buy
8310.25,3.73260642,buy
8310.02,1,buy
8310.01,0.05020402,buy
8310,1.47612053,buy
8309.89,0.00542009,buy
8309.78,0.0024,buy
8309.17,0.30721418,buy
8309.16,13,buy
8309.08,1.5,buy
8309,0.001,buy
8308.49,0.001,buy
8308.17,0.00248005,buy
8308,4.001,buy
8307.9,0.001,buy
8307.89,0.001,buy
8307.63,3.106,buy
8307.5,0.001,buy
8307.04,0.001,buy
8307,0.001,buy
8306.79,0.001,buy
8306.33,0.01,buy
8306.24,0.05787559,buy
8306.05,0.15,buy
8306,0.05839465,buy
8305.92,4.38,buy
8305.43,0.001,buy
8305,4.92406448,buy
8304.99,1.39,buy
8304.22,5,buy
8304.12,0.27,buy
8304,0.27171147,buy
8303.84,1,buy
8303.83,0.1,buy
8303.13,0.001,buy
8303,0.001,buy
8302.4,3.9,buy
8302.29,2.001,buy
8302.11,0.00224091,buy
8302,0.551,buy
8301.68,0.002,buy
8301.44,0.0024,buy
8301.33,0.35124124,buy
8301,1.6638,buy
8300.85,0.0301,buy
8300.38,0.15,buy
8300.01,1.25439006,buy
8300,28.48472626,buy
8299.98,0.26537395,buy
8299.82,0.0096,buy
8299.71,0.32757764,buy
8299.6,0.361,buy
8299.56,0.002,buy
8299.55,0.5953808,buy
8299.46,0.00229516,buy
8299.34,0.002,buy
8299.27,0.0048,buy
8299.19,0.001,buy
8299,0.2114257,buy
8298.76,0.001,buy
8298.49,0.001,buy
8298.48,0.001,buy
8298.3,4,buy
8298.19,0.001,buy
8298,0.001,buy
8297.98,0.035,buy
8297.97,0.002,buy
8297.93,0.001,buy
8297.57,0.002,buy
8297.53,0.008,buy
8297.19,0.001,buy
8297,2.70808928,buy
8296.99,0.001,buy
8296.69,0.003,buy
8296.68,0.001,buy
8296.67,0.001,buy
8296.19,0.02,buy
8296,0.007,buy
8295.95,0.01,buy
8295.63,0.171111,buy
8295.17,0.7151285,buy
8295,0.06411873,buy
8294.99,0.612,buy
8294,0.001,buy
8293.47,1.50177764,buy
8293.46,12.1640165,buy
8293.33,0.051,buy
8293.1,0.0024,buy
8293,0.001,buy
8292.98,0.035,buy
8292.66,1.238,buy
8292.29,0.13,buy
8292,0.001,buy
8291.91,0.01,buy
8291.89,0.001,buy
8291.73,0.00224034,buy
8291.68,0.003,buy
8291,0.1075992,buy
8290.17,3.46620019,buy
8290.01,1,buy
8290,73.73521326,buy
8289.99,4.32017901,buy
8289.21,0.05954094,buy
8289.2,3.01433434,buy
8289.18,0.00542742,buy
8289,0.001,buy
8288.18,0.5,buy
8288,0.001,buy
8287.98,0.035,buy
8287.96,0.001,buy
8287.55,0.001,buy
8287.5,0.02953614,buy
8287.14,0.01,buy
8287.11,0.051,buy
8287.06,0.15749611,buy
8287,0.00901331,buy
8286.68,0.002,buy
8286.54,0.002,buy
8286.52,0.01,buy
8286.47,0.00853227,buy
8286.25,0.1,buy
8286.22,0.001,buy
8286.15,0.001,buy
8286,0.251,buy
8285.99,0.001,buy
8285.43,0.06282098,buy
8285.36,0.047,buy
8285.31,0.005,buy
8285.21,0.001,buy
8285.03,0.002,buy
8285,6.97208282,buy
8284.99,0.015,buy
8284.76,0.0024,buy
8284.33,0.47059666,buy
8284.32,0.011,buy
8284,0.001,buy
8283.92,0.02001707,buy
8283.64,1.11515001,buy
8283.29,0.011,buy
8283.19,0.008,buy
8283,0.001,buy
8282.98,0.035,buy
8282.96,0.001,buy
8282.71,0.00246511,buy
8282.68,0.006,buy
8282.61,0.0048,buy
8282.15,0.001,buy
8282.12,0.004,buy
8282.01,5,buy
8282,0.5021,buy
8281.88,0.0125,buy
8281.37,0.00223627,buy
8281.22,0.001,buy
8281.21,0.001,buy
8281.12,13.281,buy
8281.01,0.001,buy
8281,0.4495,buy
8280.31,0.0125,buy
8280.3,0.011,buy
8280.15,0.0302,buy
8280.14,0.01,buy
8280,2.26537304,buy
8279.99,0.001,buy
8279.01,0.23625797,buy
8279,1.101,buy
8278.54,0.03019856,buy
8278.53,0.001,buy
8278.15,0.001,buy
8278,0.46758819,buy
8277.98,0.035,buy
8277.96,0.001,buy
8277.77,0.01,buy
8277.49,0.12528596,buy
8277.21,0.001,buy
8277.07,0.20288137,buy
8277,0.52515835,buy
8276.62,0.28456405,buy
8276.6,0.74,buy
8276.42,0.4024,buy
8276.22,0.001,buy
8276.12,0.06577967,buy
8276,0.976,buy
8275.99,0.001,buy
8275.83,0.05,buy
8275.48,0.025,buy
8275.17,0.001,buy
8275.13,0.2430353,buy
8275.01,0.011,buy
8275,13.9768169,buy
8274.99,0.015,buy
8274.72,0.012073,buy
8274.56,0.8779,buy
8274.53,0.00427808,buy
8274.51,23.6,buy
8274.17,0.001,buy
8274.15,0.001,buy
8274,2.481,buy
8273.49,0.04289273,buy
8273.36,0.001,buy
8273.33,0.001,buy
8273.21,0.001,buy
8273.14,0.01,buy
8273,0.001,buy
8272.98,0.035,buy
8272.96,0.001,buy
8272.7,0.002,buy
8272,0.05,buy
8271.71,0.1354024,buy
8271.22,0.001,buy
8271.19,0.001,buy
8271.02,0.01223735,buy
8270.63,0.001,buy
8270.55,0.105,buy
8270.15,0.001,buy
8270.01,0.021,buy
8270,71.55849844,buy
8269.99,0.001,buy
8269.15,0.001,buy
8269.14,0.01276762,buy
8268.61,0.00540243,buy
8268.45,0.002888,buy
8268.28,0.11384114,buy
8268.08,0.0024,buy
8268,0.15,buy
8267.98,0.035,buy
8267.96,0.001,buy
8267.56,0.0629177,buy
8267,0.201,buy
8266.98,0.00435641,buy
8266.49,0.0096,buy
8266.22,0.001,buy
8266.2,0.03,buy
8266.19,0.001,buy
8266.14,0.01,buy
8266,0.011,buy
8265.99,0.001,buy
8265.95,0.0048,buy
8265.03,0.001,buy
8265,1.07975072,buy
8264.99,0.015,buy
8264.89,0.00161693,buy
8264.07,0.001,buy
8264,0.001,buy
8263,0.00500097,buy
8262.98,0.035,buy
8262.33,0.06,buy
8262.01,0.471827,buy
8262,0.127,buy
8261.47,0.5,buy
8261.05,0.001,buy
8261,0.001,buy
8260.68,0.00223509,buy
8260.53,0.04,buy
8260.47,0.25,buy
8260,0.03444696,buy
8259.99,0.001,buy
8259.74,0.0024,buy
8259.47,0.079,buy
8259.33,0.0013,buy
8259.14,0.01,buy
8259,0.001,buy
8258.51,0.001514,buy
8258.19,0.001,buy
8258,0.001,buy
8257.98,0.035,buy
8257.8,0.01,buy
8257,0.051,buy
8256.88,0.25,buy
8256,0.001,buy
8255.99,0.001,buy
8255.15,0.001,buy
8255.01,0.25,buy
8255,1.126,buy
8254.99,0.015,buy
8254.06,0.5,buy
8254,1.001,buy
8253.89,0.00984148,buy
8253.75,19.75,buy
8253.46,0.02154,buy
8253.05,0.070584,buy
8253,0.261584,buy
8252.98,0.035,buy
8252.88,0.0125,buy
8252.5,0.02,buy
8252,0.58090241,buy
8251.57,0.001,buy
8251.54,0.0048893,buy
8251.51,3.782,buy
8251.4,0.87428517,buy
8251,0.0163,buy
8250.69,0.01,buy
8250.55,0.002894,buy
8250.35,0.00827781,buy
8250.17,0.001,buy
8250.01,0.07044879,buy
8250,39.52580015,buy
8249.99,0.001,buy
8249.38,0.01912902,buy
8249.3,0.25,buy
8249.29,0.0048,buy
8249.11,0.1422,buy
8249,0.25345363,buy
8248.22,0.009,buy
8248.09,0.0053826,buy
8248,0.301,buy
8247.77,0.00487834,buy
8247.39,0.079,buy
8247.15,0.001,buy
8247,0.061,buy
8246,0.001,buy
8245.99,0.001,buy
8245.1,0.00469161,buy
